<?xml version="1.0" encoding="utf-8"?>
<robot name="xarm7">
  <material name="Black">
    <color rgba="0.0 0.0 0.0 1.0" />
  </material>
  <material name="Red">
    <color rgba="0.8 0.0 0.0 1.0" />
  </material>
  <material name="White">
    <color rgba="1.0 1.0 1.0 1.0" />
  </material>
  <material name="Silver">
    <color rgba="0.753 0.753 0.753 1.0" />
  </material>
  <link name="link_base">
    <inertial>
      <origin xyz="-0.021131 -0.0016302 0.056488" rpy="0 0 0" />
      <mass value="0.88556" />
      <inertia ixx="0.0030595" ixy="0.00012259" ixz="-0.00062705" iyy="0.0037783" iyz="0.00027023" izz="0.0020125" />
    </inertial>
    <visual>
      <geometry>
        <mesh filename="meshes/xarm7/visual/link_base.obj" />
      </geometry>
      <origin xyz="0 0 0" rpy="0 0 0" />
      <material name="White" />
    </visual>
    <collision>
      <geometry>
        <mesh filename="meshes/xarm7/visual/link_base.obj" />
      </geometry>
      <origin xyz="0 0 0" rpy="0 0 0" />
    </collision>
  </link>
  <link name="link1">
    <inertial>
      <origin xyz="-0.0002 0.02905 -0.01233" rpy="0 0 0" />
      <mass value="2.382" />
      <inertia ixx="0.0056905" ixy="-1.579e-05" ixz="5.125e-06" iyy="0.0049566" iyz="-0.000873378" izz="0.003316654" />
    </inertial>
    <visual>
      <geometry>
        <mesh filename="meshes/xarm7/visual/link1.obj" />
      </geometry>
      <origin xyz="0 0 0" rpy="0 0 0" />
      <material name="White" />
    </visual>
    <collision>
      <geometry>
        <mesh filename="meshes/xarm7/visual/link1.obj" />
      </geometry>
      <origin xyz="0 0 0" rpy="0 0 0" />
    </collision>
  </link>
  <joint name="joint1" type="revolute">
    <parent link="link_base" />
    <child link="link1" />
    <axis xyz="0 0 1" />
    <limit lower="-6.283185307179586" upper="6.283185307179586" effort="50" velocity="3.14" />
    <dynamics damping="10"/>
    <!-- <dynamics damping="10" friction="1" /> -->
    <origin xyz="0 0 0.267" rpy="0 0 0" />
  </joint>
  <link name="link2">
    <inertial>
      <origin xyz="0.00022 -0.12856 0.01735" rpy="0 0 0" />
      <mass value="1.869" />
      <inertia ixx="0.0095989" ixy="1.541e-06" ixz="5.56e-06" iyy="0.00382472" iyz="-0.00317156" izz="0.007565669" />
    </inertial>
    <visual>
      <geometry>
        <mesh filename="meshes/xarm7/visual/link2.obj" />
      </geometry>
      <origin xyz="0 0 0" rpy="0 0 0" />
      <material name="White" />
    </visual>
    <collision>
      <geometry>
        <mesh filename="meshes/xarm7/visual/link2.obj" />
      </geometry>
      <origin xyz="0 0 0" rpy="0 0 0" />
    </collision>
  </link>
  <joint name="joint2" type="revolute">
    <parent link="link1" />
    <child link="link2" />
    <axis xyz="0 0 1" />
    <limit lower="-2.059" upper="2.0944" effort="50" velocity="3.14" />
    <dynamics damping="10" />
    <!-- <dynamics damping="10" friction="1" /> -->        
    <origin xyz="0 0 0" rpy="-1.5708 0 0" />
  </joint>
  <link name="link3">
    <inertial>
      <origin xyz="0.0466 -0.02463 -0.00768" rpy="0 0 0" />
      <mass value="1.6383" />
      <inertia ixx="0.00310955" ixy="0.00030837" ixz="-0.00058453" iyy="0.00264483" iyz="0.000338893" izz="0.0026624" />
    </inertial>
    <visual>
      <geometry>
        <mesh filename="meshes/xarm7/visual/link3.obj" />
      </geometry>
      <origin xyz="0 0 0" rpy="0 0 0" />
      <material name="White" />
    </visual>
    <collision>
      <geometry>
        <mesh filename="meshes/xarm7/visual/link3.obj" />
      </geometry>
      <origin xyz="0 0 0" rpy="0 0 0" />
    </collision>
  </link>
  <joint name="joint3" type="revolute">
    <parent link="link2" />
    <child link="link3" />
    <axis xyz="0 0 1" />
    <limit lower="-6.283185307179586" upper="6.283185307179586" effort="30" velocity="3.14" />
    <dynamics damping="5"/>
    <!-- <dynamics damping="5" friction="1" /> -->
    <origin xyz="0 -0.293 0" rpy="1.5708 0 0" />
  </joint>
  <link name="link4">
    <inertial>
      <origin xyz="0.07047 -0.11575 0.012" rpy="0 0 0" />
      <mass value="1.7269" />
      <inertia ixx="0.005889" ixy="0.00137112" ixz="0.00088143" iyy="0.00359703" iyz="-0.001762155" izz="0.00543244" />
    </inertial>
    <visual>
      <geometry>
        <mesh filename="meshes/xarm7/visual/link4.obj" />
      </geometry>
      <origin xyz="0 0 0" rpy="0 0 0" />
      <material name="White" />
    </visual>
    <collision>
      <geometry>
        <mesh filename="meshes/xarm7/visual/link4.obj" />
      </geometry>
      <origin xyz="0 0 0" rpy="0 0 0" />
    </collision>
  </link>
  <joint name="joint4" type="revolute">
    <parent link="link3" />
    <child link="link4" />
    <axis xyz="0 0 1" />
    <limit lower="-0.19198" upper="3.927" effort="30" velocity="3.14" />
    <dynamics damping="5" />
    <!-- <dynamics damping="5" friction="1" /> -->
    <origin xyz="0.0525 0 0" rpy="1.5708 0 0" />
  </joint>
  <link name="link5">
    <inertial>
      <origin xyz="-0.00032 0.01604 -0.026" rpy="0 0 0" />
      <mass value="1.3203" />
      <inertia ixx="0.00534665" ixy="1.5117e-05" ixz="-3.69e-07" iyy="0.0049779" iyz="-0.00022132" izz="0.0013624" />
    </inertial>
    <visual>
      <geometry>
        <mesh filename="meshes/xarm7/visual/link5.obj" />
      </geometry>
      <origin xyz="0 0 0" rpy="0 0 0" />
      <material name="White" />
    </visual>
    <collision>
      <geometry>
        <mesh filename="meshes/xarm7/visual/link5.obj" />
      </geometry>
      <origin xyz="0 0 0" rpy="0 0 0" />
    </collision>
  </link>
  <joint name="joint5" type="revolute">
    <parent link="link4" />
    <child link="link5" />
    <axis xyz="0 0 1" />
    <limit lower="-6.283185307179586" upper="6.283185307179586" effort="30" velocity="3.14" />
    <dynamics damping="5" />
    <!-- <dynamics damping="5" friction="1" /> -->
    <origin xyz="0.0775 -0.3425 0" rpy="1.5708 0 0" />
  </joint>
  <link name="link6">
    <inertial>
      <origin xyz="0.06469 0.03278 0.02141" rpy="0 0 0" />
      <mass value="1.325" />
      <inertia ixx="0.0014745" ixy="-0.000488" ixz="0.0002953" iyy="0.0019037" iyz="0.00014749" izz="0.0023652" />
    </inertial>
    <visual>
      <geometry>
        <mesh filename="meshes/xarm7/visual/link6.obj" />
      </geometry>
      <origin xyz="0 0 0" rpy="0 0 0" />
      <material name="White" />
    </visual>
    <collision>
      <geometry>
        <mesh filename="meshes/xarm7/visual/link6.obj" />
      </geometry>
      <origin xyz="0 0 0" rpy="0 0 0" />
    </collision>
  </link>
  <joint name="joint6" type="revolute">
    <parent link="link5" />
    <child link="link6" />
    <axis xyz="0 0 1" />
    <limit lower="-1.69297" upper="3.141592653589793" effort="20" velocity="3.14" />
    <dynamics damping="2" />
    <!-- <dynamics damping="2" friction="1" /> -->
    <origin xyz="0 0 0" rpy="1.5708 0 0" />
  </joint>
  <link name="link7">
    <inertial>
      <origin xyz="0 -0.00677 -0.01098" rpy="0 0 0" />
      <mass value="0.17" />
      <inertia ixx="9.3e-05" ixy="-0.0" ixz="-0.0" iyy="5.87e-05" iyz="-3.6e-06" izz="0.000132" />
    </inertial>
    <visual>
      <geometry>
        <mesh filename="meshes/xarm7/visual/link7.obj" />
      </geometry>
      <origin xyz="0 0 0" rpy="0 0 0" />
      <material name="Silver" />
    </visual>
    <collision>
      <geometry>
        <mesh filename="meshes/end_tool/collision/end_tool.obj" />
      </geometry>
      <origin xyz="0 0 0" rpy="0 0 0" />
    </collision>
  </link>
  <joint name="joint7" type="revolute">
    <parent link="link6" />
    <child link="link7" />
    <axis xyz="0 0 1" />
    <limit lower="-6.283185307179586" upper="6.283185307179586" effort="20" velocity="3.14" />
    <dynamics damping="2" />
    <!-- <dynamics damping="2" friction="1" /> -->
    <origin xyz="0.076 0.097 0" rpy="-1.5708 0 0" />
  </joint>
  <transmission name="tran1">
    <type>transmission_interface/SimpleTransmission</type>
    <joint name="joint1">
      <hardwareInterface>hardware_interface/EffortJointInterface</hardwareInterface>
    </joint>
    <actuator name="motor1">
      <hardwareInterface>hardware_interface/EffortJointInterface</hardwareInterface>
      <mechanicalReduction>1</mechanicalReduction>
    </actuator>
  </transmission>
  <transmission name="tran2">
    <type>transmission_interface/SimpleTransmission</type>
    <joint name="joint2">
      <hardwareInterface>hardware_interface/EffortJointInterface</hardwareInterface>
    </joint>
    <actuator name="motor2">
      <hardwareInterface>hardware_interface/EffortJointInterface</hardwareInterface>
      <mechanicalReduction>1</mechanicalReduction>
    </actuator>
  </transmission>
  <transmission name="tran3">
    <type>transmission_interface/SimpleTransmission</type>
    <joint name="joint3">
      <hardwareInterface>hardware_interface/EffortJointInterface</hardwareInterface>
    </joint>
    <actuator name="motor3">
      <hardwareInterface>hardware_interface/EffortJointInterface</hardwareInterface>
      <mechanicalReduction>1</mechanicalReduction>
    </actuator>
  </transmission>
  <transmission name="tran4">
    <type>transmission_interface/SimpleTransmission</type>
    <joint name="joint4">
      <hardwareInterface>hardware_interface/EffortJointInterface</hardwareInterface>
    </joint>
    <actuator name="motor4">
      <hardwareInterface>hardware_interface/EffortJointInterface</hardwareInterface>
      <mechanicalReduction>1</mechanicalReduction>
    </actuator>
  </transmission>
  <transmission name="tran5">
    <type>transmission_interface/SimpleTransmission</type>
    <joint name="joint5">
      <hardwareInterface>hardware_interface/EffortJointInterface</hardwareInterface>
    </joint>
    <actuator name="motor5">
      <hardwareInterface>hardware_interface/EffortJointInterface</hardwareInterface>
      <mechanicalReduction>1</mechanicalReduction>
    </actuator>
  </transmission>
  <transmission name="tran6">
    <type>transmission_interface/SimpleTransmission</type>
    <joint name="joint6">
      <hardwareInterface>hardware_interface/EffortJointInterface</hardwareInterface>
    </joint>
    <actuator name="motor6">
      <hardwareInterface>hardware_interface/EffortJointInterface</hardwareInterface>
      <mechanicalReduction>1</mechanicalReduction>
    </actuator>
  </transmission>
  <transmission name="tran7">
    <type>transmission_interface/SimpleTransmission</type>
    <joint name="joint7">
      <hardwareInterface>hardware_interface/EffortJointInterface</hardwareInterface>
    </joint>
    <actuator name="motor7">
      <hardwareInterface>hardware_interface/EffortJointInterface</hardwareInterface>
      <mechanicalReduction>1</mechanicalReduction>
    </actuator>
  </transmission>

  <!-- Within joint limits, link4, link5, link6, and link7 cannot self-collide-->
  <drake:collision_filter_group name="link_4_5_6_7">
    <drake:member link="link4"/>
    <drake:member link="link5"/>
    <drake:member link="link6"/>
    <drake:member link="link7"/>
    <drake:ignored_collision_filter_group name="link_4_5_6_7"/>
  </drake:collision_filter_group>  
  
</robot>
